{
 "cells": [
  {
   "cell_type": "code",
   "execution_count": null,
   "metadata": {},
   "outputs": [
    {
     "ename": "",
     "evalue": "",
     "output_type": "error",
     "traceback": [
      "\u001b[1;31mThe kernel failed to start as 'TypeAlias' could not be imported from 'c:\\dclv\\rasa\\rasa_1\\myenv\\lib\\site-packages\\typing_extensions.py'.\n",
      "\u001b[1;31mClick <a href='https://aka.ms/kernelFailuresModuleImportErrFromFile'>here</a> for more info."
     ]
    }
   ],
   "source": [
    "\n",
    "import logging\n",
    "from typing import Text\n",
    "\n",
    "from rasa.core.agent import Agent\n",
    "# from rasa.shared.utils.cli import print_info, print_success\n",
    "# from rasa.shared.utils.io import json_to_string"
   ]
  },
  {
   "cell_type": "code",
   "execution_count": 8,
   "metadata": {},
   "outputs": [],
   "source": [
    "import logging\n",
    "import asyncio\n",
    "from rasa.core.agent import Agent"
   ]
  },
  {
   "cell_type": "code",
   "execution_count": 3,
   "metadata": {},
   "outputs": [
    {
     "name": "stderr",
     "output_type": "stream",
     "text": [
      "\u001b[93mc:\\dclv\\rasa\\rasa_1\\rasa_dclv\\rasa\\shared\\core\\slot_mappings.py:213: UserWarning: Slot auto-fill has been removed in 3.0 and replaced with a new explicit mechanism to set slots. Please refer to https://rasa.com/docs/rasa/domain#slots to learn more.\n",
      "  rasa.shared.utils.io.raise_warning(\n",
      "\u001b[0mc:\\dclv\\rasa\\rasa_1\\myenv\\lib\\site-packages\\tensorflow\\python\\framework\\indexed_slices.py:447: UserWarning: Converting sparse IndexedSlices(IndexedSlices(indices=Tensor(\"gradients/cond_grad/gradients/cond/GatherV2_grad/Reshape_1:0\", shape=(None,), dtype=int32), values=Tensor(\"gradients/cond_grad/gradients/cond/GatherV2_grad/Reshape:0\", shape=(None,), dtype=float32), dense_shape=Tensor(\"gradients/cond_grad/gradients/cond/GatherV2_grad/Cast:0\", shape=(1,), dtype=int32))) to a dense Tensor of unknown shape. This may consume a large amount of memory.\n",
      "  warnings.warn(\n",
      "\u001b[93mc:\\dclv\\rasa\\rasa_1\\rasa_dclv\\rasa\\utils\\train_utils.py:528: UserWarning: constrain_similarities is set to `False`. It is recommended to set it to `True` when using cross-entropy loss.\n",
      "  rasa.shared.utils.io.raise_warning(\n",
      "\u001b[0m\u001b[93mc:\\dclv\\rasa\\rasa_1\\rasa_dclv\\rasa\\shared\\core\\slot_mappings.py:213: UserWarning: Slot auto-fill has been removed in 3.0 and replaced with a new explicit mechanism to set slots. Please refer to https://rasa.com/docs/rasa/domain#slots to learn more.\n",
      "  rasa.shared.utils.io.raise_warning(\n",
      "\u001b[0mc:\\dclv\\rasa\\rasa_1\\myenv\\lib\\site-packages\\tensorflow\\python\\framework\\indexed_slices.py:447: UserWarning: Converting sparse IndexedSlices(IndexedSlices(indices=Tensor(\"gradients/cond_grad/Identity_1:0\", shape=(None,), dtype=int64), values=Tensor(\"gradients/cond_grad/Identity:0\", shape=(None,), dtype=float32), dense_shape=Tensor(\"gradients/cond_grad/Identity_2:0\", shape=(1,), dtype=int32))) to a dense Tensor of unknown shape. This may consume a large amount of memory.\n",
      "  warnings.warn(\n",
      "c:\\dclv\\rasa\\rasa_1\\myenv\\lib\\site-packages\\tensorflow\\python\\framework\\indexed_slices.py:447: UserWarning: Converting sparse IndexedSlices(IndexedSlices(indices=Tensor(\"gradients/cond_1_grad/Identity_1:0\", shape=(None,), dtype=int64), values=Tensor(\"gradients/cond_1_grad/Identity:0\", shape=(None,), dtype=float32), dense_shape=Tensor(\"gradients/cond_1_grad/Identity_2:0\", shape=(1,), dtype=int32))) to a dense Tensor of unknown shape. This may consume a large amount of memory.\n",
      "  warnings.warn(\n"
     ]
    }
   ],
   "source": [
    "logger = logging.getLogger(__name__)\n",
    "\n",
    "model_path = \"C:/dclv/rasa/rasa_1/rasa_dclv/models/20230525-232400-dark-basis.tar.gz\"\n",
    "agent = Agent.load(model_path)\n",
    "\n"
   ]
  },
  {
   "cell_type": "code",
   "execution_count": 18,
   "metadata": {},
   "outputs": [
    {
     "ename": "NameError",
     "evalue": "name 'UserMessage' is not defined",
     "output_type": "error",
     "traceback": [
      "\u001b[1;31m---------------------------------------------------------------------------\u001b[0m",
      "\u001b[1;31mNameError\u001b[0m                                 Traceback (most recent call last)",
      "Cell \u001b[1;32mIn[18], line 1\u001b[0m\n\u001b[1;32m----> 1\u001b[0m user_message \u001b[39m=\u001b[39m UserMessage(\n\u001b[0;32m      2\u001b[0m         \u001b[39m'\u001b[39m\u001b[39mHow do i sign up?\u001b[39m\u001b[39m'\u001b[39m,\n\u001b[0;32m      3\u001b[0m         metadata\u001b[39m=\u001b[39m{\u001b[39m'\u001b[39m\u001b[39mcontext\u001b[39m\u001b[39m'\u001b[39m: \u001b[39m'\u001b[39m\u001b[39mstores\u001b[39m\u001b[39m'\u001b[39m},\n\u001b[0;32m      4\u001b[0m     )\n",
      "\u001b[1;31mNameError\u001b[0m: name 'UserMessage' is not defined"
     ]
    }
   ],
   "source": [
    "user_message = UserMessage(\n",
    "        'How do i sign up?',\n",
    "        metadata={'context': 'stores'},\n",
    "    )"
   ]
  },
  {
   "cell_type": "code",
   "execution_count": 25,
   "metadata": {},
   "outputs": [
    {
     "name": "stderr",
     "output_type": "stream",
     "text": [
      "\u001b[93mc:\\dclv\\rasa\\rasa_1\\rasa_dclv\\rasa\\shared\\core\\slot_mappings.py:213: UserWarning: Slot auto-fill has been removed in 3.0 and replaced with a new explicit mechanism to set slots. Please refer to https://rasa.com/docs/rasa/domain#slots to learn more.\n",
      "  rasa.shared.utils.io.raise_warning(\n",
      "\u001b[0mc:\\dclv\\rasa\\rasa_1\\myenv\\lib\\site-packages\\tensorflow\\python\\framework\\traceable_stack.py:119: RuntimeWarning: coroutine 'Agent.parse_message' was never awaited\n",
      "  return reversed(self._stack)\n",
      "RuntimeWarning: Enable tracemalloc to get the object allocation traceback\n",
      "c:\\dclv\\rasa\\rasa_1\\myenv\\lib\\site-packages\\tensorflow\\python\\framework\\indexed_slices.py:447: UserWarning: Converting sparse IndexedSlices(IndexedSlices(indices=Tensor(\"gradients/cond_grad/gradients/cond/GatherV2_grad/Reshape_1:0\", shape=(None,), dtype=int32), values=Tensor(\"gradients/cond_grad/gradients/cond/GatherV2_grad/Reshape:0\", shape=(None,), dtype=float32), dense_shape=Tensor(\"gradients/cond_grad/gradients/cond/GatherV2_grad/Cast:0\", shape=(1,), dtype=int32))) to a dense Tensor of unknown shape. This may consume a large amount of memory.\n",
      "  warnings.warn(\n",
      "\u001b[93mc:\\dclv\\rasa\\rasa_1\\rasa_dclv\\rasa\\utils\\train_utils.py:528: UserWarning: constrain_similarities is set to `False`. It is recommended to set it to `True` when using cross-entropy loss.\n",
      "  rasa.shared.utils.io.raise_warning(\n",
      "\u001b[0mc:\\dclv\\rasa\\rasa_1\\myenv\\lib\\site-packages\\tensorflow\\python\\framework\\indexed_slices.py:447: UserWarning: Converting sparse IndexedSlices(IndexedSlices(indices=Tensor(\"gradients/cond_grad/Identity_1:0\", shape=(None,), dtype=int64), values=Tensor(\"gradients/cond_grad/Identity:0\", shape=(None,), dtype=float32), dense_shape=Tensor(\"gradients/cond_grad/Identity_2:0\", shape=(1,), dtype=int32))) to a dense Tensor of unknown shape. This may consume a large amount of memory.\n",
      "  warnings.warn(\n",
      "c:\\dclv\\rasa\\rasa_1\\myenv\\lib\\site-packages\\tensorflow\\python\\framework\\indexed_slices.py:447: UserWarning: Converting sparse IndexedSlices(IndexedSlices(indices=Tensor(\"gradients/cond_1_grad/Identity_1:0\", shape=(None,), dtype=int64), values=Tensor(\"gradients/cond_1_grad/Identity:0\", shape=(None,), dtype=float32), dense_shape=Tensor(\"gradients/cond_1_grad/Identity_2:0\", shape=(1,), dtype=int32))) to a dense Tensor of unknown shape. This may consume a large amount of memory.\n",
      "  warnings.warn(\n"
     ]
    },
    {
     "ename": "RuntimeError",
     "evalue": "asyncio.run() cannot be called from a running event loop",
     "output_type": "error",
     "traceback": [
      "\u001b[1;31m---------------------------------------------------------------------------\u001b[0m",
      "\u001b[1;31mRuntimeError\u001b[0m                              Traceback (most recent call last)",
      "Cell \u001b[1;32mIn[25], line 6\u001b[0m\n\u001b[0;32m      4\u001b[0m agent \u001b[39m=\u001b[39m Agent\u001b[39m.\u001b[39mload(model_path)\n\u001b[0;32m      5\u001b[0m message \u001b[39m=\u001b[39m \u001b[39m\"\u001b[39m\u001b[39mXin chÃ o\u001b[39m\u001b[39m\"\u001b[39m\n\u001b[1;32m----> 6\u001b[0m result \u001b[39m=\u001b[39m asyncio\u001b[39m.\u001b[39;49mrun(agent\u001b[39m.\u001b[39;49mparse_message(message))\n\u001b[0;32m      7\u001b[0m \u001b[39mprint\u001b[39m(result)\n",
      "File \u001b[1;32mC:\\Program Files\\Python38\\lib\\asyncio\\runners.py:33\u001b[0m, in \u001b[0;36mrun\u001b[1;34m(main, debug)\u001b[0m\n\u001b[0;32m      9\u001b[0m \u001b[39m\u001b[39m\u001b[39m\"\"\"Execute the coroutine and return the result.\u001b[39;00m\n\u001b[0;32m     10\u001b[0m \n\u001b[0;32m     11\u001b[0m \u001b[39mThis function runs the passed coroutine, taking care of\u001b[39;00m\n\u001b[1;32m   (...)\u001b[0m\n\u001b[0;32m     30\u001b[0m \u001b[39m    asyncio.run(main())\u001b[39;00m\n\u001b[0;32m     31\u001b[0m \u001b[39m\"\"\"\u001b[39;00m\n\u001b[0;32m     32\u001b[0m \u001b[39mif\u001b[39;00m events\u001b[39m.\u001b[39m_get_running_loop() \u001b[39mis\u001b[39;00m \u001b[39mnot\u001b[39;00m \u001b[39mNone\u001b[39;00m:\n\u001b[1;32m---> 33\u001b[0m     \u001b[39mraise\u001b[39;00m \u001b[39mRuntimeError\u001b[39;00m(\n\u001b[0;32m     34\u001b[0m         \u001b[39m\"\u001b[39m\u001b[39masyncio.run() cannot be called from a running event loop\u001b[39m\u001b[39m\"\u001b[39m)\n\u001b[0;32m     36\u001b[0m \u001b[39mif\u001b[39;00m \u001b[39mnot\u001b[39;00m coroutines\u001b[39m.\u001b[39miscoroutine(main):\n\u001b[0;32m     37\u001b[0m     \u001b[39mraise\u001b[39;00m \u001b[39mValueError\u001b[39;00m(\u001b[39m\"\u001b[39m\u001b[39ma coroutine was expected, got \u001b[39m\u001b[39m{!r}\u001b[39;00m\u001b[39m\"\u001b[39m\u001b[39m.\u001b[39mformat(main))\n",
      "\u001b[1;31mRuntimeError\u001b[0m: asyncio.run() cannot be called from a running event loop"
     ]
    }
   ],
   "source": [
    "logger = logging.getLogger(__name__)\n",
    "\n",
    "model_path = \"C:/dclv/rasa/rasa_1/rasa_dclv/models/20230525-232400-dark-basis.tar.gz\"\n",
    "agent = Agent.load(model_path)\n",
    "message = \"Xin chÃ o\"\n",
    "result = agent.parse_message(message)\n",
    "print(result)\n"
   ]
  }
 ],
 "metadata": {
  "kernelspec": {
   "display_name": "myenv",
   "language": "python",
   "name": "python3"
  },
  "language_info": {
   "codemirror_mode": {
    "name": "ipython",
    "version": 3
   },
   "file_extension": ".py",
   "mimetype": "text/x-python",
   "name": "python",
   "nbconvert_exporter": "python",
   "pygments_lexer": "ipython3",
   "version": "3.8.10"
  },
  "orig_nbformat": 4
 },
 "nbformat": 4,
 "nbformat_minor": 2
}
